# Objective-C 的异常
熟悉Java编程的对异常机制一定有非常深刻的印象, Objective-C 也提供类似的异常机制, 不过OC异常机制并不作为常规的编程实践, 通常只是作为一种程序调度, 捕捉机制
   

## 看一个例子
```objc
#import <Foundation/Foundation.h>
int main(int argc, const char * argv[]) {
    @autoreleasepool {
        
        id car = [[NSObject alloc] init];
        
        [car performSelector:@selector(run)];
    }
    return 0;
}

```

### 分析
* 上面这段代码由于 NSObject 中 并没有实现 run 方法, 会导致程序崩溃 
* - [NSObject run]: unrecognized selector sent to instance 0x1002034c0
* 这是我们最常见的异常, 为了避免这种异常, 我们一般会在 调用方法时, 对 消息接收者做一判断,如下:

```objc
if([car responseSelector:@selector(run)]){
	[car performSelector:@selector(run)];
}

```
* 除了上面这种方法来避免程序在运行过程中崩溃, 还可以用 异常处理机制


## @try....@catch....@finally
### @try
* 我们平常正常处理代码的区域
* 可以将代码写在这里面
* 出现异常后, 用 @catch 来捕捉


### @catch
* 用来捕捉 异常
* 里面对应异常后的处理


### @finally
* 回收资源


### 语法
```objc
@try{
	// 业务逻辑代码

}
@catch (NSException *ex1){
	// 处理异常1的 code...
}
@catch (NSException *ex2){
	// 处理异常2的 code...
}
@catch (NSException_subclass *ex3)
........
// 可能有更多的 @catch 

@finally{
	//回收资源
}


```


### 过程
* @try
	- 正常执行代码..
	- 出现异常后, 系统自动生成一个异常对象
	- 异常被提交给系统
	- 这个过程被称为 抛出 (throw) 异常
* @catch
	- 系统接收到异常后, 产生异常对象(NSException或NSException的子类)
	- 调用中断处理
	- 中断处理的代码就是去 寻找 能处理该异常的 @catch
	- 根据产生的异常类 一个一个去 @catch 后的参数 匹配
	- 一旦匹配到了, 就立即执行这个 @catch
	- 这个过程被称为捕捉异常
	- 如果找不到 能处理 这个异常的 @catch 那么 程序就会崩溃
* NSException 是OC所有异常类的根类, 其他异常都应该通过他来派生
	- 是 @catch 捕捉到的 异常对象
	- 必须是 NSException 类 (或者是 子类)
	- 由于 捕获异常 是一个一个往下走的, 所以如果自定义了异常(MYException)后, 将自定义的异常放在最前面,这样对会有机会执行, 因为 如果 NSException 在前面的话, 进入这个 @catch(NSException * ep) 时, 由于 MYException是NSException的子类, 这个 @catch还是会被执行, 那么我们自定义的 @catch(MYException *)就不会执行

###### PS: 不管程序代码块是否牌@try , 只要执行了该代码块时出了异常, 系统总会生成一个 异常对象, 如何为该异常对象寻找 @catch ? 当运行环境接收到异常后, 会依次判断该异常是否是 @catch 后 异常类或其子类的实例, 如果是, 运行环境将调用该@catch 块来处理异常; 否则再次用该异常对象和下一个 @catch 块里的异常类进行比较...


#### 注意
* 当程序进入异常处理的 @catch 块时, 系统生生成的异常对象 ex 将会传给 @catch 块后的 异常形参, 从而允许 catch 块通过该 ex 来 获得异常的 详细信息

* @try 后可以多个 @catch 块, 这是为了针对不同的异常类提供不同的异常处理方式,当系统发生不同的意外情况时, 会生成不同的异常对象, 运行环境会根据该异常对象所属的异常类来决定使用哪个 @catch 来处理异常
* @try 块被执行一次
* 出现异常只会执行一个 @catch, 不会有多个被执行, 除非 goto
* @try 的 "{"  "}" 不能省略, 即使 @try 中只有一行代码也不能省
* @catch 和 @try 一样 不能省略 "{  }"
* 声明在 @try 块中的变量是局部变量, 只在 @try 中,不能 @catch中访问


### 修改上面的程序
```objc
int main(int argc, const char * argv[]) {
    @autoreleasepool {
        @try{
            id car = [[NSObject alloc] init];
            
            [car performSelector:@selector(run)];
  
        }@catch (NSException *ep1){
            NSLog(@"捕捉到了异常 %@",ep1);
        }@finally{
            
        }
        NSLog(@"程序没有崩溃, 来到了这里");
    }
    return 0;
}

LOG:
2017-08-13 16:05:43.500193+0800 异常[1811:102071] -[NSObject run]: unrecognized selector sent to instance 0x100506bb0
2017-08-13 16:05:43.501205+0800 异常[1811:102071] 捕捉到了异常 -[NSObject run]: unrecognized selector sent to instance 0x100506bb0
2017-08-13 16:05:43.501234+0800 异常[1811:102071] 程序没有崩溃, 来到了这里

```


### 访问异常信息 (NSException)
* name  该异常详细的名称
* reason 返回引发异常的原因
* userInfo 返回引发该异常的用户附加信息, 该方法的返回值是一个NSDictionary对象
* 上面这些 都能 getter 出来


## @finally
### 什么时候用
* @try 中打开了一些 资源(如: 数据库连接, 网络连接, 磁盘文件等等), 这些物理资源都必须显示回收, 在没有使用 arc 机制的情况下, 所有对象上用的内存都必须显示回收, 这都是在 @finally中完成 的

### @finally 执行的时机
* 只要在 @catch 后给出了 @finally, 那么不管@try有没有出现异常, 或者 @catch是否被执行, 哪个被执行, 都会调用 @finally, 甚至@try @catch中 return, @finally 也会被执行

* 异常处理语法 中 @try 是必须的, @catch 和 @finally 是可选的, 但是 @catch 和 @finally必须出现其一, @finally 必须在 所有@catch之后, 所有的 @catch 必须在@try后, @try只能有一个, 自定义的异常 必须放在 父类 NSException的前面

* 通常情况下, 不要在 @finally 块中使用如 return 或 @throw 等导致方法终止的语句, 一旦@finally块中使用了 return 或 @throw 语句, 将会导致 @try 块以及 @catch 块中 return @throw 语句失效


* 下面这段代码 我们本来的意愿是在 @try 中结束代码段(block), 但是由于 @finally中出现了 return, 所以 block是在 @finally中被终止了, 并没有回到 @try中去 return

```objc

int main(int argc, const char * argv[]) {
    @autoreleasepool {
        
        BOOL ok = YES;
        
        BOOL (^ block)() = ^{
            
            @try
            {
                printf("调用block ing.. @try %d\n",ok);
                return NO;
            }
            
            @finally
            {
                printf("调用block ing.. @try %d\n",ok);
                return YES;
            }
        };
        printf("调用block之前 %d\n",ok);
        ok = block();
        printf("调用block之前 %d\n",ok);
        
    }
    
    return 0;
}

LOG:
调用block之前 1
调用block ing.. @try 1
调用block ing.. @finally 1
调用block之前 1

// 最后 ok == 1 , 说明 ok 的值没有被修改, 说明 @finally return YES后, 这个代码段就结束了, 没有回到 @try 去返回(return NO)



```

###### PS: 当 @try 或 @catch 中出 return 或 @throw 时, 是想结束掉当前的 @try...@catch...@fianlly 的代码段, 根据语法, 当出现 @finally时, 必须要执行, 所以会在 @try 或 @catch 中 return 之前 先去 @finally中执行, 等到@finally 的代码执行完毕后, 会回到 @try 或 @catch 中 return来结束 整个 @try...@catch...@finally, 但是如果 @finally中出现了 return后, 那行 终止 整个 @try...@catch...@finally 是在 @finally中, 不会回到 @try 或 @catch去终止

**正常回到 @try 中**

```objc
int main(int argc, const char * argv[]) {
    @autoreleasepool {
        
        @try {
            NSLog(@"try return 之前");
            return 0 ;
        } @catch (NSException *exception) {
            
        } @finally {
            NSLog(@"try return 之前来到了 @finally中");
        }
        
    }
    NSLog(@"@try整个代码段后 来到了 这里");
    return 0;
}

LOG:
2017-08-13 17:14:58.818279+0800 异常[2020:136777] try return 之前
2017-08-13 17:14:58.818462+0800 异常[2020:136777] try return 之前来到了 @finally中

//第三个没打印 说明 回到了 @try中 return了

```

####  这个例子在上面的那个例子, 则说明了 @finally中出现 return后, 不会回到 @try中




## 抛出异常与自定义异常类

### 手动抛出异常 (@throw ExceptionInstace;)
* 大部分情况下, 我们直接抛出异常 (NSException) 对象即可
* 少数情况下, 可以抛出自定义的异常类, 此时可通过异常的类名来包含一些异常的信息
* 抛出异常 是抛出一个异常的实例, 不是类



### 自定义异常类
* 自定义的异常类需继承 NSException
* 自定义的异常类需要我们自己手动 抛出, 不能由系统自动去抛出

```objc
@interface MYException : NSException
@implementation MYException : NSException
@end

int ages(int age){
    if(age<0){
        MYException *ex = [[MYException alloc] initWithName:@"出现异常" reason:@"年龄不合法" userInfo:nil];
        @throw ex;
    }
    return age;
}

int main(int argc, const char * argv[]) {
    @autoreleasepool {
        @try {
            int age;
            age = ages( -10);  NSLog(@"%d",age);
        } @catch (MYException *exception) {
            NSLog(@"%@ %@",exception.name,exception.reason);
        } @finally {
            NSLog(@"回收资源");
        }
        
        
    }
    return 0;
}

@end 


LOG:
2017-08-13 17:44:08.915236+0800 异常[2104:152610] 出现异常 年龄不合法
2017-08-13 17:44:08.915611+0800 异常[2104:152610] 回收资源
```



